<?xml version="1.0"?>
<robot name="awesome-o" xmlns:xacro="http://www.ros.org/wiki/xacro">
<xacro:macro name="arm" params="prefix reflect base">
<link name="${prefix}_shoulder">
<visual>
<geometry>
<box size="0.03 0.04 0.03"/>
</geometry>
<origin rpy="0 0 0" xyz="0.0 0 0.00"/>
<material name="blue">
<color rgba="0 0 .8 1"/>
</material>
</visual>
</link>
<joint name="${base+1}:base_to_${prefix}_shoulder" type="revolute">
<parent link="base_link"/>
<child link="${prefix}_shoulder"/>
<origin rpy="1.5 0 0" xyz="${reflect*0.070} 0 0.03"/>
<axis xyz="${reflect} 0 0"/>
<limit effort="1000.0" lower="-3.14" upper="3.14" velocity="0.5"/>
</joint>
<link name="${prefix}_upper_arm">
    <visual>
      <geometry>
      <!--mesh filename="file:///home/local/AX12.dae" scale="0.0001 0.0001 0.0001"/-->
      <box size="0.03 0.04 0.09"/>
      </geometry>
      <material name="green">
        <color rgba="0 .8 0 1"/>
      </material>
      <origin rpy="0 0 0" xyz="0.00 0 -0.045"/>
    </visual>
</link>
  <joint name="${base+3}:${prefix}_shoulder_to_upper" type="revolute">
    <parent link="${prefix}_shoulder"/>
    <child link="${prefix}_upper_arm"/>
    <origin rpy="0 ${reflect*-1.5} 0" xyz="0.00 0 0.0"/>
    <axis xyz="0 -1 0"/>
    <limit effort="1000.0" lower="-3.14" upper="3.14" velocity="0.5"/>
  </joint>
<link name="${prefix}_forearm">
    <visual>
      <geometry>
      <!--mesh filename="file:///home/local/AX12.dae" scale="0.0001 0.0001 0.0001"/-->
      <box size="0.03 0.04 0.09"/>
      </geometry>
      <material name="blue"/>
      <origin rpy="0 0 0" xyz="0.00 0 -0.045"/>
    </visual>
</link>
  <joint name="${base+5}:${prefix}_elbow" type="revolute">
    <parent link="${prefix}_upper_arm"/>
    <child link="${prefix}_forearm"/>
    <origin rpy="0 0 0" xyz="0.00 0 -0.08"/>
    <axis xyz="0 -1 0"/>
    <limit effort="1000.0" lower="-3.14" upper="3.14" velocity="0.5"/>
  </joint>
</xacro:macro>

<xacro:macro name="leg" params="prefix reflect base">
<link name="${prefix}_hip">
	<visual>
		<geometry>
			<box size="0.03 0.04 0.03"/>
		</geometry>
		<origin rpy="0 0 0" xyz="0.0 0 0.00"/>
		<material name="blue">
		<color rgba="0 0 .8 1"/>
		</material>
	</visual>
</link>
<joint name="${base+7}:base_to_${prefix}_hip" type="revolute">
	<parent link="base_link"/>
	<child link="${prefix}_hip"/>
	<origin rpy="0 0 ${reflect*-0.70}" xyz="${reflect*0.030} 0 -0.06"/>
	<axis xyz="0 0 -1"/>
	<limit effort="1000.0" lower="-3.14" upper="3.14" velocity="0.5"/>
</joint>
<link name="${prefix}_hip_split">
    <visual>
      <geometry>
      <box size="0.03 0.04 0.03"/>
      </geometry>
      <material name="red">
			<color rgba="1 .0 .0 1"/>
			</material>
      <origin rpy="0 0 0" xyz="0.00 0 -0.045"/>
    </visual>
</link>
<joint name="${base+9}:${prefix}_hip_to_split" type="revolute">
<parent link="${prefix}_hip"/>
<child link="${prefix}_hip_split"/>
<origin rpy="0 0 0" xyz="0.00 0 0.0"/>
<axis xyz="0 1 0"/>
<limit effort="1000.0" lower="-3.14" upper="3.14" velocity="0.5"/>
</joint>
<link name="${prefix}_upper_leg">
    <visual>
      <geometry>
      <box size="0.03 0.04 0.09"/>
      </geometry>
      <material name="green"/>
      <origin rpy="0 0 0" xyz="0.00 0 -0.045"/>
    </visual>
</link>
  <joint name="${base+11}:${prefix}_hip_split_to_upper" type="revolute">
    <parent link="${prefix}_hip_split"/>
    <child link="${prefix}_upper_leg"/>
    <origin rpy="0 0 0" xyz="0.00 0 0.0"/>
    <axis xyz="${reflect*-1} 0 0"/>
    <limit effort="1000.0" lower="-3.14" upper="3.14" velocity="0.5"/>
  </joint>
<link name="${prefix}_calf">
    <visual>
      <geometry>
      <!--mesh filename="file:///home/local/AX12.dae" scale="0.0001 0.0001 0.0001"/-->
      <box size="0.03 0.04 0.09"/>
      </geometry>
      <material name="blue"/>
      <origin rpy="0 0 0" xyz="0.00 0 -0.045"/>
    </visual>
</link>
  <joint name="${base+13}:${prefix}_knee" type="revolute">
    <parent link="${prefix}_upper_leg"/>
    <child link="${prefix}_calf"/>
    <origin rpy="0 0 0" xyz="0.00 0 -0.08"/>
    <axis xyz="${reflect*1} 0 0"/>
    <limit effort="1000.0" lower="-3.14" upper="3.14" velocity="0.5"/>
  </joint>
<link name="${prefix}_foot">
    <visual>
      <geometry>
      <box size="0.05 0.075 0.05"/>
      </geometry>
      <material name="green"/>
      <origin rpy="0 0 0" xyz="0.00 0 -0.045"/>
    </visual>
</link>
  <joint name="${base+15}:${prefix}_ankle" type="revolute">
    <parent link="${prefix}_calf"/>
    <child link="${prefix}_foot"/>
    <origin rpy="0 0 0" xyz="0.00 0 -0.045"/>
    <axis xyz="${reflect} 0 0"/>
    <limit effort="1000.0" lower="-3.14" upper="3.14" velocity="0.5"/>
  </joint>
<link name="${prefix}_foot_pad">
    <visual>
      <geometry>
      <box size="0.06 0.10 0.005"/>
      </geometry>
      <material name="blue"/>
      <origin rpy="0 0 0" xyz="0.00 0 -0.045"/>
    </visual>
</link>
  <joint name="${base+17}:${prefix}_ankle_roll" type="revolute">
    <parent link="${prefix}_foot"/>
    <child link="${prefix}_foot_pad"/>
    <origin rpy="0 0 0" xyz="0.00 0 -0.03"/>
    <axis xyz="0 -1 0"/>
    <limit effort="1000.0" lower="-3.14" upper="3.14" velocity="0.5"/>
  </joint>
</xacro:macro>

<link name="base_link">
<visual>
<geometry>
<box size="0.11 0.05 0.12"/>
</geometry>
</visual>
</link>
<xacro:arm prefix="right" reflect="1" base="0"/>
<xacro:arm prefix="left" reflect="-1" base="1"/>
<xacro:leg prefix="right" reflect="1" base="0"/>
<xacro:leg prefix="left" reflect="-1" base="1"/>
</robot>
